Workbook

Sheet Single input 
L1: PRIMARY | P1: SECONDARY | R1: TERTIARY | W1: TOTAL PER PALLET | AD1: TOTAL PER ORDER
A2: Material number | B2: Quantity | L2: PAP | M2: CPAP | N2: HDPE | O2: PP | P2: PAP | Q2: #PPperSP | R2: FOR | S2: PAP | T2: LDPE | U2: PET | V2: #SPperTP | W2: FOR | X2: PAP | Y2: CPAP | Z2: PP | AA2: LDPE | AB2: PET | AC2: HDPE | AD2: FOR | AE2: PAP | AF2: CPAP | AG2: PP | AH2: LDPE | AI2: PET | AJ2: HDPE
K3: =VLOOKUP($A3,Data!$D$3:$CJ$128,30,FALSE) -> #N/A | L3: =VLOOKUP($A3,Data!$D$3:$CJ$128,64,FALSE) -> #N/A | M3: =VLOOKUP($A3,Data!$D$3:$CJ$128,65,FALSE) -> #N/A | N3: =VLOOKUP($A3,Data!$D$3:$CJ$128,66,FALSE) -> #N/A | O3: =VLOOKUP($A3,Data!$D$3:$CJ$128,67,FALSE) -> #N/A | P3: =VLOOKUP($A3,Data!$D$3:$CJ$128,68,FALSE) -> #N/A | Q3: =VLOOKUP($A3,Data!$D$3:$CJ$128,69,FALSE) -> #N/A | R3: =VLOOKUP($A3,Data!$D$3:$CJ$128,70,FALSE) -> #N/A | S3: =VLOOKUP($A3,Data!$D$3:$CJ$128,71,FALSE) -> #N/A | T3: =VLOOKUP($A3,Data!$D$3:$CJ$128,72,FALSE) -> #N/A | U3: =VLOOKUP($A3,Data!$D$3:$CJ$128,73,FALSE) -> #N/A | V3: =VLOOKUP($A3,Data!$D$3:$CJ$128,74,FALSE) -> #N/A | W3: =R3 -> #N/A | X3: =(((L3/1000)*Q3)+((P3/1000)*V3)+(S3/1000)) -> #N/A | Y3: =(((M3/1000)*Q3)*V3) -> #N/A | Z3: =(O3/1000)*Q3 -> #N/A | AA3: =T3/1000 -> #N/A | AB3: =U3/1000 -> #N/A | AC3: =(N3/1000)*Q3 -> #N/A | AD3: =$B3*W3 -> #N/A | AE3: =$B3*X3 -> #N/A | AF3: =$B3*Y3 -> #N/A | AG3: =$B3*Z3 -> #N/A | AH3: =$B3*AA3 -> #N/A | AI3: =$B3*AB3 -> #N/A | AJ3: =$B3*AC3 -> #N/A
A5: =K3 -> #N/A
A8: Totals per | B8: PALLET | C8: ORDER
A9: FOR | B9: =W3 -> #N/A | C9: =AD3 -> #N/A
A10: PAP | B10: =X3 -> #N/A | C10: =AE3 -> #N/A
A11: LDPE | B11: =AA3 -> #N/A | C11: =AH3 -> #N/A
A12: PET | B12: =AB3 -> #N/A | C12: =AI3 -> #N/A
A13: HDPE | B13: =AC3 -> #N/A | C13: =AJ3 -> #N/A
A14: PP | B14: =Z3 -> #N/A | C14: =AG3 -> #N/A
A16: PRIMARY
A17: =L2 -> PAP | B17: =L3 -> #N/A
A18: =M2 -> CPAP | B18: =M3 -> #N/A
A19: =N2 -> HDPE | B19: =N3 -> #N/A
A20: =O2 -> PP | B20: =O3 -> #N/A
A22: SECONDARY | B22: =Q3 -> #N/A | C22: PP per SP
A23: =P2 -> PAP | B23: =P3 -> #N/A
A25: TERTIARY | B25: =V3 -> #N/A | C25: SP per TP
A26: =R2 -> FOR | B26: =R3 -> #N/A
A27: =S2 -> PAP | B27: =S3 -> #N/A
A28: =T2 -> LDPE | B28: =T3 -> #N/A
A29: =U2 -> PET | B29: =U3 -> #N/A

Sheet Batch input
A1: Material number | B1: Quantity | D1: Totals
D2: FOR | E2: =('Batch details'!B432)/5 -> 0
D3: PAP | E3: ='Batch details'!B431 -> 0
D4: LDPE | E4: ='Batch details'!B434 -> 0
D5: PET | E5: ='Batch details'!B433 -> 0
D6: HDPE | E6: ='Batch details'!B436 -> 0
D7: PP | E7: ='Batch details'!B435 -> 0

Sheet Batch details
D1: PRIMARY | G1: SECONDARY | I1: TERTIARY | N1: TOTAL PER PALLET | T1: TOTAL PER ORDER
A2: Article number | B2: Quantity | D2: PAP | E2: HDPE | F2: PP | G2: PAP | H2: #PPperSP | I2: FOR | J2: PAP | K2: LDPE | L2: PET | M2: #SPperTP | N2: FOR | O2: PAP | P2: PP | Q2: LDPE | R2: PET | S2: HDPE | T2: FOR | U2: PAP | V2: PP | W2: LDPE | X2: PET | Y2: HDPE
A3: ='Batch input'!A2 -> 0 | B3: ='Batch input'!B2 -> 0 | C3: =VLOOKUP($A3,Data!$D$3:$CJ$128,30,FALSE) -> #N/A | D3: =VLOOKUP($A3,Data!$D$3:$CJ$128,64,FALSE) -> #N/A | E3: =VLOOKUP($A3,Data!$D$3:$CJ$128,66,FALSE) -> #N/A | F3: =VLOOKUP($A3,Data!$D$3:$CJ$128,67,FALSE) -> #N/A | G3: =VLOOKUP($A3,Data!$D$3:$CJ$128,68,FALSE) -> #N/A | H3: =VLOOKUP($A3,Data!$D$3:$CJ$128,69,FALSE) -> #N/A | I3: =VLOOKUP($A3,Data!$D$3:$CJ$128,70,FALSE) -> #N/A | J3: =VLOOKUP($A3,Data!$D$3:$CJ$128,71,FALSE) -> #N/A | K3: =VLOOKUP($A3,Data!$D$3:$CJ$128,72,FALSE) -> #N/A | L3: =VLOOKUP($A3,Data!$D$3:$CJ$128,73,FALSE) -> #N/A | M3: =VLOOKUP($A3,Data!$D$3:$CJ$128,74,FALSE) -> #N/A | N3: =I3 -> #N/A | O3: =(((D3/1000)*H3)+((G3/1000)*M3)+(J3/1000)) -> #N/A | P3: =(F3/1000)*H3 -> #N/A | Q3: =K3/1000 -> #N/A | R3: =L3/1000 -> #N/A | S3: =(E3/1000)*H3 -> #N/A | T3: =$B3*N3 -> #N/A | U3: =$B3*O3 -> #N/A | V3: =$B3*P3 -> #N/A | W3: =$B3*Q3 -> #N/A | X3: =$B3*R3 -> #N/A | Y3: =$B3*S3 -> #N/A
A4: ='Batch input'!A3 -> 0 | B4: ='Batch input'!B3 -> 0 | C4: =VLOOKUP($A4,Data!$D$3:$CJ$128,30,FALSE) -> #N/A | D4: =VLOOKUP($A4,Data!$D$3:$CJ$128,64,FALSE) -> #N/A | E4: =VLOOKUP($A4,Data!$D$3:$CJ$128,66,FALSE) -> #N/A | F4: =VLOOKUP($A4,Data!$D$3:$CJ$128,67,FALSE) -> #N/A | G4: =VLOOKUP($A4,Data!$D$3:$CJ$128,68,FALSE) -> #N/A | H4: =VLOOKUP($A4,Data!$D$3:$CJ$128,69,FALSE) -> #N/A | I4: =VLOOKUP($A4,Data!$D$3:$CJ$128,70,FALSE) -> #N/A | J4: =VLOOKUP($A4,Data!$D$3:$CJ$128,71,FALSE) -> #N/A | K4: =VLOOKUP($A4,Data!$D$3:$CJ$128,72,FALSE) -> #N/A | L4: =VLOOKUP($A4,Data!$D$3:$CJ$128,73,FALSE) -> #N/A | M4: =VLOOKUP($A4,Data!$D$3:$CJ$128,74,FALSE) -> #N/A | N4: =I4 -> #N/A | O4: =(((D4/1000)*H4)+((G4/1000)*M4)+(J4/1000)) -> #N/A | P4: =(F4/1000)*H4 -> #N/A | Q4: =K4/1000 -> #N/A | R4: =L4/1000 -> #N/A | S4: =(E4/1000)*H4 -> #N/A | T4: =$B4*N4 -> #N/A | U4: =$B4*O4 -> #N/A | V4: =$B4*P4 -> #N/A | W4: =$B4*Q4 -> #N/A | X4: =$B4*R4 -> #N/A | Y4: =$B4*S4 -> #N/A
A5: ='Batch input'!A4 -> 0 | B5: ='Batch input'!B4 -> 0 | C5: =VLOOKUP($A5,Data!$D$3:$CJ$128,30,FALSE) -> #N/A | D5: =VLOOKUP($A5,Data!$D$3:$CJ$128,64,FALSE) -> #N/A | E5: =VLOOKUP($A5,Data!$D$3:$CJ$128,66,FALSE) -> #N/A | F5: =VLOOKUP($A5,Data!$D$3:$CJ$128,67,FALSE) -> #N/A | G5: =VLOOKUP($A5,Data!$D$3:$CJ$128,68,FALSE) -> #N/A | H5: =VLOOKUP($A5,Data!$D$3:$CJ$128,69,FALSE) -> #N/A | I5: =VLOOKUP($A5,Data!$D$3:$CJ$128,70,FALSE) -> #N/A | J5: =VLOOKUP($A5,Data!$D$3:$CJ$128,71,FALSE) -> #N/A | K5: =VLOOKUP($A5,Data!$D$3:$CJ$128,72,FALSE) -> #N/A | L5: =VLOOKUP($A5,Data!$D$3:$CJ$128,73,FALSE) -> #N/A | M5: =VLOOKUP($A5,Data!$D$3:$CJ$128,74,FALSE) -> #N/A | N5: =I5 -> #N/A | O5: =(((D5/1000)*H5)+((G5/1000)*M5)+(J5/1000)) -> #N/A | P5: =(F5/1000)*H5 -> #N/A | Q5: =K5/1000 -> #N/A | R5: =L5/1000 -> #N/A | S5: =(E5/1000)*H5 -> #N/A | T5: =$B5*N5 -> #N/A | U5: =$B5*O5 -> #N/A | V5: =$B5*P5 -> #N/A | W5: =$B5*Q5 -> #N/A | X5: =$B5*R5 -> #N/A | Y5: =$B5*S5 -> #N/A
A6: ='Batch input'!A5 -> 0 | B6: ='Batch input'!B5 -> 0 | C6: =VLOOKUP($A6,Data!$D$3:$CJ$128,30,FALSE) -> #N/A | D6: =VLOOKUP($A6,Data!$D$3:$CJ$128,64,FALSE) -> #N/A | E6: =VLOOKUP($A6,Data!$D$3:$CJ$128,66,FALSE) -> #N/A | F6: =VLOOKUP($A6,Data!$D$3:$CJ$128,67,FALSE) -> #N/A | G6: =VLOOKUP($A6,Data!$D$3:$CJ$128,68,FALSE) -> #N/A | H6: =VLOOKUP($A6,Data!$D$3:$CJ$128,69,FALSE) -> #N/A | I6: =VLOOKUP($A6,Data!$D$3:$CJ$128,70,FALSE) -> #N/A | J6: =VLOOKUP($A6,Data!$D$3:$CJ$128,71,FALSE) -> #N/A | K6: =VLOOKUP($A6,Data!$D$3:$CJ$128,72,FALSE) -> #N/A | L6: =VLOOKUP($A6,Data!$D$3:$CJ$128,73,FALSE) -> #N/A | M6: =VLOOKUP($A6,Data!$D$3:$CJ$128,74,FALSE) -> #N/A | N6: =I6 -> #N/A | O6: =(((D6/1000)*H6)+((G6/1000)*M6)+(J6/1000)) -> #N/A | P6: =(F6/1000)*H6 -> #N/A | Q6: =K6/1000 -> #N/A | R6: =L6/1000 -> #N/A | S6: =(E6/1000)*H6 -> #N/A | T6: =$B6*N6 -> #N/A | U6: =$B6*O6 -> #N/A | V6: =$B6*P6 -> #N/A | W6: =$B6*Q6 -> #N/A | X6: =$B6*R6 -> #N/A | Y6: =$B6*S6 -> #N/A
A7: ='Batch input'!A6 -> 0 | B7: ='Batch input'!B6 -> 0 | C7: =VLOOKUP($A7,Data!$D$3:$CJ$128,30,FALSE) -> #N/A | D7: =VLOOKUP($A7,Data!$D$3:$CJ$128,64,FALSE) -> #N/A | E7: =VLOOKUP($A7,Data!$D$3:$CJ$128,66,FALSE) -> #N/A | F7: =VLOOKUP($A7,Data!$D$3:$CJ$128,67,FALSE) -> #N/A | G7: =VLOOKUP($A7,Data!$D$3:$CJ$128,68,FALSE) -> #N/A | H7: =VLOOKUP($A7,Data!$D$3:$CJ$128,69,FALSE) -> #N/A | I7: =VLOOKUP($A7,Data!$D$3:$CJ$128,70,FALSE) -> #N/A | J7: =VLOOKUP($A7,Data!$D$3:$CJ$128,71,FALSE) -> #N/A | K7: =VLOOKUP($A7,Data!$D$3:$CJ$128,72,FALSE) -> #N/A | L7: =VLOOKUP($A7,Data!$D$3:$CJ$128,73,FALSE) -> #N/A | M7: =VLOOKUP($A7,Data!$D$3:$CJ$128,74,FALSE) -> #N/A | N7: =I7 -> #N/A | O7: =(((D7/1000)*H7)+((G7/1000)*M7)+(J7/1000)) -> #N/A | P7: =(F7/1000)*H7 -> #N/A | Q7: =K7/1000 -> #N/A | R7: =L7/1000 -> #N/A | S7: =(E7/1000)*H7 -> #N/A | T7: =$B7*N7 -> #N/A | U7: =$B7*O7 -> #N/A | V7: =$B7*P7 -> #N/A | W7: =$B7*Q7 -> #N/A | X7: =$B7*R7 -> #N/A | Y7: =$B7*S7 -> #N/A
A8: ='Batch input'!A7 -> 0 | B8: ='Batch input'!B7 -> 0 | C8: =VLOOKUP($A8,Data!$D$3:$CJ$128,30,FALSE) -> #N/A | D8: =VLOOKUP($A8,Data!$D$3:$CJ$128,64,FALSE) -> #N/A | E8: =VLOOKUP($A8,Data!$D$3:$CJ$128,66,FALSE) -> #N/A | F8: =VLOOKUP($A8,Data!$D$3:$CJ$128,67,FALSE) -> #N/A | G8: =VLOOKUP($A8,Data!$D$3:$CJ$128,68,FALSE) -> #N/A | H8: =VLOOKUP($A8,Data!$D$3:$CJ$128,69,FALSE) -> #N/A | I8: =VLOOKUP($A8,Data!$D$3:$CJ$128,70,FALSE) -> #N/A | J8: =VLOOKUP($A8,Data!$D$3:$CJ$128,71,FALSE) -> #N/A | K8: =VLOOKUP($A8,Data!$D$3:$CJ$128,72,FALSE) -> #N/A | L8: =VLOOKUP($A8,Data!$D$3:$CJ$128,73,FALSE) -> #N/A | M8: =VLOOKUP($A8,Data!$D$3:$CJ$128,74,FALSE) -> #N/A | N8: =I8 -> #N/A | O8: =(((D8/1000)*H8)+((G8/1000)*M8)+(J8/1000)) -> #N/A | P8: =(F8/1000)*H8 -> #N/A | Q8: =K8/1000 -> #N/A | R8: =L8/1000 -> #N/A | S8: =(E8/1000)*H8 -> #N/A | T8: =$B8*N8 -> #N/A | U8: =$B8*O8 -> #N/A | V8: =$B8*P8 -> #N/A | W8: =$B8*Q8 -> #N/A | X8: =$B8*R8 -> #N/A | Y8: =$B8*S8 -> #N/A
A9: ='Batch input'!A8 -> 0 | B9: ='Batch input'!B8 -> 0 | C9: =VLOOKUP($A9,Data!$D$3:$CJ$128,30,FALSE) -> #N/A | D9: =VLOOKUP($A9,Data!$D$3:$CJ$128,64,FALSE) -> #N/A | E9: =VLOOKUP($A9,Data!$D$3:$CJ$128,66,FALSE) -> #N/A | F9: =VLOOKUP($A9,Data!$D$3:$CJ$128,67,FALSE) -> #N/A | G9: =VLOOKUP($A9,Data!$D$3:$CJ$128,68,FALSE) -> #N/A | H9: =VLOOKUP($A9,Data!$D$3:$CJ$128,69,FALSE) -> #N/A | I9: =VLOOKUP($A9,Data!$D$3:$CJ$128,70,FALSE) -> #N/A | J9: =VLOOKUP($A9,Data!$D$3:$CJ$128,71,FALSE) -> #N/A | K9: =VLOOKUP($A9,Data!$D$3:$CJ$128,72,FALSE) -> #N/A | L9: =VLOOKUP($A9,Data!$D$3:$CJ$128,73,FALSE) -> #N/A | M9: =VLOOKUP($A9,Data!$D$3:$CJ$128,74,FALSE) -> #N/A | N9: =I9 -> #N/A | O9: =(((D9/1000)*H9)+((G9/1000)*M9)+(J9/1000)) -> #N/A | P9: =(F9/1000)*H9 -> #N/A | Q9: =K9/1000 -> #N/A | R9: =L9/1000 -> #N/A | S9: =(E9/1000)*H9 -> #N/A | T9: =$B9*N9 -> #N/A | U9: =$B9*O9 -> #N/A | V9: =$B9*P9 -> #N/A | W9: =$B9*Q9 -> #N/A | X9: =$B9*R9 -> #N/A | Y9: =$B9*S9 -> #N/A
A10: ='Batch input'!A9 -> 0 | B10: ='Batch input'!B9 -> 0 | C10: =VLOOKUP($A10,Data!$D$3:$CJ$128,30,FALSE) -> #N/A | D10: =VLOOKUP($A10,Data!$D$3:$CJ$128,64,FALSE) -> #N/A | E10: =VLOOKUP($A10,Data!$D$3:$CJ$128,66,FALSE) -> #N/A | F10: =VLOOKUP($A10,Data!$D$3:$CJ$128,67,FALSE) -> #N/A | G10: =VLOOKUP($A10,Data!$D$3:$CJ$128,68,FALSE) -> #N/A | H10: =VLOOKUP($A10,Data!$D$3:$CJ$128,69,FALSE) -> #N/A | I10: =VLOOKUP($A10,Data!$D$3:$CJ$128,70,FALSE) -> #N/A | J10: =VLOOKUP($A10,Data!$D$3:$CJ$128,71,FALSE) -> #N/A | K10: =VLOOKUP($A10,Data!$D$3:$CJ$128,72,FALSE) -> #N/A | L10: =VLOOKUP($A10,Data!$D$3:$CJ$128,73,FALSE) -> #N/A | M10: =VLOOKUP($A10,Data!$D$3:$CJ$128,74,FALSE) -> #N/A | N10: =I10 -> #N/A | O10: =(((D10/1000)*H10)+((G10/1000)*M10)+(J10/1000)) -> #N/A | P10: =(F10/1000)*H10 -> #N/A | Q10: =K10/1000 -> #N/A | R10: =L10/1000 -> #N/A | S10: =(E10/1000)*H10 -> #N/A | T10: =$B10*N10 -> #N/A | U10: =$B10*O10 -> #N/A | V10: =$B10*P10 -> #N/A | W10: =$B10*Q10 -> #N/A | X10: =$B10*R10 -> #N/A | Y10: =$B10*S10 -> #N/A
A11: ='Batch input'!A10 -> 0 | B11: ='Batch input'!B10 -> 0 | C11: =VLOOKUP($A11,Data!$D$3:$CJ$128,30,FALSE) -> #N/A | D11: =VLOOKUP($A11,Data!$D$3:$CJ$128,64,FALSE) -> #N/A | E11: =VLOOKUP($A11,Data!$D$3:$CJ$128,66,FALSE) -> #N/A | F11: =VLOOKUP($A11,Data!$D$3:$CJ$128,67,FALSE) -> #N/A | G11: =VLOOKUP($A11,Data!$D$3:$CJ$128,68,FALSE) -> #N/A | H11: =VLOOKUP($A11,Data!$D$3:$CJ$128,69,FALSE) -> #N/A | I11: =VLOOKUP($A11,Data!$D$3:$CJ$128,70,FALSE) -> #N/A | J11: =VLOOKUP($A11,Data!$D$3:$CJ$128,71,FALSE) -> #N/A | K11: =VLOOKUP($A11,Data!$D$3:$CJ$128,72,FALSE) -> #N/A | L11: =VLOOKUP($A11,Data!$D$3:$CJ$128,73,FALSE) -> #N/A | M11: =VLOOKUP($A11,Data!$D$3:$CJ$128,74,FALSE) -> #N/A | N11: =I11 -> #N/A | O11: =(((D11/1000)*H11)+((G11/1000)*M11)+(J11/1000)) -> #N/A | P11: =(F11/1000)*H11 -> #N/A | Q11: =K11/1000 -> #N/A | R11: =L11/1000 -> #N/A | S11: =(E11/1000)*H11 -> #N/A | T11: =$B11*N11 -> #N/A | U11: =$B11*O11 -> #N/A | V11: =$B11*P11 -> #N/A | W11: =$B11*Q11 -> #N/A | X11: =$B11*R11 -> #N/A | Y11: =$B11*S11 -> #N/A
A12: ='Batch input'!A11 -> 0 | B12: ='Batch input'!B11 -> 0 | C12: =VLOOKUP($A12,Data!$D$3:$CJ$128,30,FALSE) -> #N/A | D12: =VLOOKUP($A12,Data!$D$3:$CJ$128,64,FALSE) -> #N/A | E12: =VLOOKUP($A12,Data!$D$3:$CJ$128,66,FALSE) -> #N/A | F12: =VLOOKUP($A12,Data!$D$3:$CJ$128,67,FALSE) -> #N/A | G12: =VLOOKUP($A12,Data!$D$3:$CJ$128,68,FALSE) -> #N/A | H12: =VLOOKUP($A12,Data!$D$3:$CJ$128,69,FALSE) -> #N/A | I12: =VLOOKUP($A12,Data!$D$3:$CJ$128,70,FALSE) -> #N/A | J12: =VLOOKUP($A12,Data!$D$3:$CJ$128,71,FALSE) -> #N/A | K12: =VLOOKUP($A12,Data!$D$3:$CJ$128,72,FALSE) -> #N/A | L12: =VLOOKUP($A12,Data!$D$3:$CJ$128,73,FALSE) -> #N/A | M12: =VLOOKUP($A12,Data!$D$3:$CJ$128,74,FALSE) -> #N/A | N12: =I12 -> #N/A | O12: =(((D12/1000)*H12)+((G12/1000)*M12)+(J12/1000)) -> #N/A | P12: =(F12/1000)*H12 -> #N/A | Q12: =K12/1000 -> #N/A | R12: =L12/1000 -> #N/A | S12: =(E12/1000)*H12 -> #N/A | T12: =$B12*N12 -> #N/A | U12: =$B12*O12 -> #N/A | V12: =$B12*P12 -> #N/A | W12: =$B12*Q12 -> #N/A | X12: =$B12*R12 -> #N/A | Y12: =$B12*S12 -> #N/A
A13: ='Batch input'!A12 -> 0 | B13: ='Batch input'!B12 -> 0 | C13: =VLOOKUP($A13,Data!$D$3:$CJ$128,30,FALSE) -> #N/A | D13: =VLOOKUP($A13,Data!$D$3:$CJ$128,64,FALSE) -> #N/A | E13: =VLOOKUP($A13,Data!$D$3:$CJ$128,66,FALSE) -> #N/A | F13: =VLOOKUP($A13,Data!$D$3:$CJ$128,67,FALSE) -> #N/A | G13: =VLOOKUP($A13,Data!$D$3:$CJ$128,68,FALSE) -> #N/A | H13: =VLOOKUP($A13,Data!$D$3:$CJ$128,69,FALSE) -> #N/A | I13: =VLOOKUP($A13,Data!$D$3:$CJ$128,70,FALSE) -> #N/A | J13: =VLOOKUP($A13,Data!$D$3:$CJ$128,71,FALSE) -> #N/A | K13: =VLOOKUP($A13,Data!$D$3:$CJ$128,72,FALSE) -> #N/A | L13: =VLOOKUP($A13,Data!$D$3:$CJ$128,73,FALSE) -> #N/A | M13: =VLOOKUP($A13,Data!$D$3:$CJ$128,74,FALSE) -> #N/A | N13: =I13 -> #N/A | O13: =(((D13/1000)*H13)+((G13/1000)*M13)+(J13/1000)) -> #N/A | P13: =(F13/1000)*H13 -> #N/A | Q13: =K13/1000 -> #N/A | R13: =L13/1000 -> #N/A | S13: =(E13/1000)*H13 -> #N/A | T13: =$B13*N13 -> #N/A | U13: =$B13*O13 -> #N/A | V13: =$B13*P13 -> #N/A | W13: =$B13*Q13 -> #N/A | X13: =$B13*R13 -> #N/A | Y13: =$B13*S13 -> #N/A
A14: ='Batch input'!A13 -> 0 | B14: ='Batch input'!B13 -> 0 | C14: =VLOOKUP($A14,Data!$D$3:$CJ$128,30,FALSE) -> #N/A | D14: =VLOOKUP($A14,Data!$D$3:$CJ$128,64,FALSE) -> #N/A | E14: =VLOOKUP($A14,Data!$D$3:$CJ$128,66,FALSE) -> #N/A | F14: =VLOOKUP($A14,Data!$D$3:$CJ$128,67,FALSE) -> #N/A | G14: =VLOOKUP($A14,Data!$D$3:$CJ$128,68,FALSE) -> #N/A | H14: =VLOOKUP($A14,Data!$D$3:$CJ$128,69,FALSE) -> #N/A | I14: =VLOOKUP($A14,Data!$D$3:$CJ$128,70,FALSE) -> #N/A | J14: =VLOOKUP($A14,Data!$D$3:$CJ$128,71,FALSE) -> #N/A | K14: =VLOOKUP($A14,Data!$D$3:$CJ$128,72,FALSE) -> #N/A | L14: =VLOOKUP($A14,Data!$D$3:$CJ$128,73,FALSE) -> #N/A | M14: =VLOOKUP($A14,Data!$D$3:$CJ$128,74,FALSE) -> #N/A | N14: =I14 -> #N/A | O14: =(((D14/1000)*H14)+((G14/1000)*M14)+(J14/1000)) -> #N/A | P14: =(F14/1000)*H14 -> #N/A | Q14: =K14/1000 -> #N/A | R14: =L14/1000 -> #N/A | S14: =(E14/1000)*H14 -> #N/A | T14: =$B14*N14 -> #N/A | U14: =$B14*O14 -> #N/A | V14: =$B14*P14 -> #N/A | W14: =$B14*Q14 -> #N/A | X14: =$B14*R14 -> #N/A | Y14: =$B14*S14 -> #N/A
... A428: ='Batch input'!A427 -> 0 | B428: ='Batch input'!B427 -> 0 | C428: =VLOOKUP($A428,Data!$D$3:$CJ$128,30,FALSE) -> #N/A | D428: =VLOOKUP($A428,Data!$D$3:$CJ$128,64,FALSE) -> #N/A | E428: =VLOOKUP($A428,Data!$D$3:$CJ$128,66,FALSE) -> #N/A | F428: =VLOOKUP($A428,Data!$D$3:$CJ$128,67,FALSE) -> #N/A | G428: =VLOOKUP($A428,Data!$D$3:$CJ$128,68,FALSE) -> #N/A | H428: =VLOOKUP($A428,Data!$D$3:$CJ$128,69,FALSE) -> #N/A | I428: =VLOOKUP($A428,Data!$D$3:$CJ$128,70,FALSE) -> #N/A | J428: =VLOOKUP($A428,Data!$D$3:$CJ$128,71,FALSE) -> #N/A | K428: =VLOOKUP($A428,Data!$D$3:$CJ$128,72,FALSE) -> #N/A | L428: =VLOOKUP($A428,Data!$D$3:$CJ$128,73,FALSE) -> #N/A | M428: =VLOOKUP($A428,Data!$D$3:$CJ$128,74,FALSE) -> #N/A | N428: =I428 -> #N/A | O428: =(((D428/1000)*H428)+((G428/1000)*M428)+(J428/1000)) -> #N/A | P428: =(F428/1000)*H428 -> #N/A | Q428: =K428/1000 -> #N/A | R428: =L428/1000 -> #N/A | S428: =(E428/1000)*H428 -> #N/A | T428: =$B428*N428 -> #N/A | U428: =$B428*O428 -> #N/A | V428: =$B428*P428 -> #N/A | W428: =$B428*Q428 -> #N/A | X428: =$B428*R428 -> #N/A | Y428: =$B428*S428 -> #N/A
A429: Totals | B429: =SUM(B3:B428) -> 0 | T429: =_xlfn.AGGREGATE(9,6,T3:T428) -> 0 | U429: =_xlfn.AGGREGATE(9,6,U3:U428) -> 0 | V429: =_xlfn.AGGREGATE(9,6,V3:V428) -> 0 | W429: =_xlfn.AGGREGATE(9,6,W3:W428) -> 0 | X429: =_xlfn.AGGREGATE(9,6,X3:X428) -> 0 | Y429: =_xlfn.AGGREGATE(9,6,Y3:Y428) -> 0
A431: Paper | B431: =U429 -> 0
A432: Wood | B432: =T429 -> 0
A433: PET | B433: =X429 -> 0
A434: LDPE | B434: =W429 -> 0
A435: PP | B435: =V429 -> 0
A436: HDPE | B436: =Y429 -> 0
B438: =SUM(B433:B436,B431) -> 0

Sheet Data
A1: 2e pricelist Wendy | B1: Pricelist Wendy | D1: List Pierre | BO1: PRIMARY | BS1: SECONDARY | BU1: TERTIARY | BZ1: TOTAL PER PALLET
D2: Item number | E2: Product status | F2: Price list | G2: Product hierarchy | H2: Product line | I2: Product description | J2: Long description | K2: Primary converters | L2: PSE required converters | M2: UOM | N2: Paper weight | O2: Detailed paper weight | P2: Number of plys | Q2: Paper quality | R2: Paper colour | S2: Country of origin | T2: EAN1 | U2: EAN3 | V2: Dimensions UOM | W2: Detail - Length of paper | X2: Detail-width of paper | Y2: Miscellaneous | Z2: Yield | AA2: Net weight of UOM | AB2: Roll diameter | AC2: Pack height | AD2: HS code | AE2: Pallet type | AF2: Bulk-Half pallet | AG2: Pallet description | AH2: Pallet length (m) | AI2: numberUOMperPallet | AJ2: Pallet width (m) | AK2: Pallet height (m) | AL2: Pallet dimensions | AM2: REACH Compliant | AN2: Gross weight pallet | AO2: Net weight pallet | AP2: PAP codes | AQ2: FSC product claim | AR2: FSC number | AS2: RoHS Compliant | AT2: Food safety (indirect) | AU2: Alternative fiber | AV2: Comm-Fresh fiber | AW2: Comm-Recycled fibers | AX2: Comm-Alternative fibers | AY2: Detail-Fresh fiber | AZ2: Detail-PIR | BA2: Detail-PCR | BB2: Fossil fuel use (MJ) | BC2: GHG emissions | BD2: Water use | BE2: Product pictures | BF2: Material safety datasheet | BG2: Product hierarchy narrative | BH2: Quality narrative | BI2: Created | BJ2: Created By | BK2: Title | BL2: Title | BM2: Is a Raja ref | BO2: PAP | BP2: CPAP | BQ2: HDPE | BR2: PP | BS2: PAP | BT2: #PPperSP | BU2: FOR | BV2: PAP | BW2: LDPE | BX2: PET | BY2: #SPperTP | BZ2: FOR | CA2: PAP | CB2: CPAP | CC2: PP | CD2: LDPE | CE2: PET | CF2: HDPE | CG2: Plastic 4 | CI2: Check
A3: 10000096 | B3: 10000096 | D3: 10000096 | E3: Active | F3: Yes | G3: Cushioning | H3: PadPak Compact | I3: PP Pack 1p 0.38*360m 70gsm PK | L3: PadPak Compact ; Fillpak Trident ; Fillpak Trident mini ; Fillpak Table Top cutter ; WrapPak Protector | M3: Pack | N3: 70gsm | O3: 70,0 g/m2 +/- 2,5 g/m² | P3: 1 | Q3: Premium Kraft | R3: Brown | S3: European Union | T3: 8721284290001 | V3: 0.38 x 360m | W3: 360 ± 4 | X3: 380 -1 +5 | AA3: 9.7 | AC3: 23 ± 3 | AD3: 48043158 | AE3: Euro | AG3: 48*PMF 70 360m | AH3: 0.8 | AI3: 48 | AJ3: 1.2 | AK3: 1.2 | AL3: 0.80 x 1.20 x 1.20m | AM3: Yes | AN3: 486 ±19 | AO3: 464 | AP3: PAP22 | AQ3: FSC Mix Credit | AR3: FSC-C134738 | AS3: RoHS Compliant | AT3: Yes | AV3: 0.85 | AW3: 0.15 | AY3: 0.85 | AZ3: 0 | BA3: 0.15 | BB3: 125 | BC3: 12 | BD3: 4.1 | BE3: - | BF3: - | BG3: Cushioning is used to protect fragile items during shipping. Packages are often handled with little or no care during transport, so precautions are needed to prevent damage. Shocks and vibration are controlled by cushioning, significantly reducing broken box contents and subsequent returns | BH3: Made using fresh renewable fibers from sustainably managed forests, Ranpak’s Premium Kraft paper provides superior protective performance. Designed to minimize CO2 emissions while fully curbside recyclable, Premium Kraft protects the planet as well as your goods. | BI3: 08/16/2024 11:03 AM | BJ3: Vu, Pierre | BM3: True | BO3: ='LookUp Roll&Packs'!$U$9 -> 43.19 | BR3: ='LookUp Roll&Packs'!$V$9 -> 5.22 | BT3: =AI3 -> 48 | BU3: ='LookUp Roll&Packs'!$BI$9 -> 22.56 | BV3: ='LookUp Roll&Packs'!$CO$9 -> 2796.7 | BW3: ='LookUp Roll&Packs'!$CQ$9 -> 175.14 | BX3: ='LookUp Roll&Packs'!$CP$9 -> 66.8 | BY3: 1 | BZ3: =BU3 -> 22.56 | CA3: =((BT3*BO3)+(BS3*BY3)+BV3)/1000 -> 4.86982 | CC3: =(BT3*BR3)/1000 -> 0.25056 | CD3: =BW3/1000 -> 0.17514 | CE3: =BX3/1000 -> 0.0668 | CH3: x | CI3: x | CJ3: x
A4: 10000097 | B4: 10000097 | D4: 10000097 | E4: Active | F4: Yes | G4: Cushioning | H4: PadPak Compact | I4: PP Pack 1p 0.38*360m 70gsm PK W. | L4: PadPak Compact ; Fillpak Trident ; Fillpak Trident bulk ; Fillpak Trident mini ; Fillpak Trident mini bulk ; Fillpak Table Top cutter ; WrapPak Protector ; | M4: Pack | N4: 70gsm | O4: 70,0 g/m2 +/- 2,5 g/m² | P4: 1 | Q4: Premium Kraft | R4: White | S4: European Union | T4: 8721284290018 | V4: 0.38 x 360m | W4: 360 ± 4 | X4: 380 -1 +5 | Y4: White | AA4: 9.5 | AC4: 23 ± 3 | AD4: 48043158 | AE4: Euro | AG4: 48*PMF 70 360m White | AH4: 0.8 | AI4: 48 | AJ4: 1.2 | AK4: 1.2 | AL4: 0.80 x 1.20 x 1.20m | AM4: Yes | AN4: 486 ±19 | AO4: 458 | AP4: PAP22 | AQ4: FSC Mix Credit | AR4: FSC-C134738 | AS4: RoHS Compliant | AT4: Yes | AV4: 0.85 | AW4: 0.15 | AY4: 0.85 | AZ4: 0 | BA4: 0.15 | BB4: 133 | BC4: 12 | BD4: 5.5 | BE4: - | BF4: - | BG4: Cushioning is used to protect fragile items during shipping. Packages are often handled with little or no care during transport, so precautions are needed to prevent damage. Shocks and vibration are controlled by cushioning, significantly reducing broken box contents and subsequent returns | BH4: Made using fresh renewable fibers from sustainably managed forests, Ranpak’s Premium Kraft paper provides superior protective performance. Designed to minimize CO2 emissions while fully curbside recyclable, Premium Kraft protects the planet as well as your goods. | BI4: 08/16/2024 11:03 AM | BJ4: Vu, Pierre | BM4: True | BO4: ='LookUp Roll&Packs'!$U$9 -> 43.19 | BR4: ='LookUp Roll&Packs'!$V$9 -> 5.22 | BT4: =AI4 -> 48 | BU4: ='LookUp Roll&Packs'!$BI$9 -> 22.56 | BV4: ='LookUp Roll&Packs'!$CO$9 -> 2796.7 | BW4: ='LookUp Roll&Packs'!$CQ$9 -> 175.14 | BX4: ='LookUp Roll&Packs'!$CP$9 -> 66.8 | BY4: 1 | BZ4: =BU4 -> 22.56 | CA4: =((AI4*BO4)+BV4)/1000 -> 4.86982 | CC4: =(AI4*BR4)/1000 -> 0.25056 | CD4: =BW4/1000 -> 0.17514 | CE4: =BX4/1000 -> 0.0668 | CH4: x | CI4: x | CJ4: x
A5: 10000098 | B5: 10000098 | D5: 10000098 | E5: Active | F5: Yes | G5: Cushioning | H5: PadPak Compact | I5: PP Pack 1p 0.38*360m 70gsm PK T. | L5: PadPak Compact ; Fillpak Trident ; Fillpak Trident bulk ; Fillpak Trident mini ; Fillpak Trident mini bulk ; Fillpak Table Top cutter ; WrapPak Protector ; | M5: Pack | N5: 70gsm | O5: 70,0 g/m2 +/- 2,5 g/m² | P5: 1 | Q5: Premium Kraft | R5: Brown | S5: European Union | T5: 8721284290025 | V5: 0.38 x 360m | W5: 360 ± 4 | X5: 380 -1 +5 | Y5: Tape | AA5: 9.7 | AC5: 23 ± 3 | AD5: 48043158 | AE5: Euro | AG5: 48*PMF 70 360m tape | AH5: 0.8 | AI5: 48 | AJ5: 1.2 | AK5: 1.2 | AL5: 0.80 x 1.20 x 1.20m | AM5: Yes | AN5: 486 ±19 | AO5: 464 | AP5: PAP22 | AQ5: FSC Mix Credit | AR5: FSC-C134738 | AS5: RoHS Compliant | AT5: Yes | AV5: 0.85 | AW5: 0.15 | AY5: 0.85 | AZ5: 0 | BA5: 0.15 | BB5: 125 | BC5: 12 | BD5: 4.1 | BE5: - | BF5: - | BG5: Cushioning is used to protect fragile items during shipping. Packages are often handled with little or no care during transport, so precautions are needed to prevent damage. Shocks and vibration are controlled by cushioning, significantly reducing broken box contents and subsequent returns | BH5: Made using fresh renewable fibers from sustainably managed forests, Ranpak’s Premium Kraft paper provides superior protective performance. Designed to minimize CO2 emissions while fully curbside recyclable, Premium Kraft protects the planet as well as your goods. | BI5: 08/16/2024 11:03 AM | BJ5: Vu, Pierre | BM5: True | BO5: ='LookUp Roll&Packs'!$U$9 -> 43.19 | BR5: ='LookUp Roll&Packs'!$V$9 -> 5.22 | BT5: =AI5 -> 48 | BU5: ='LookUp Roll&Packs'!$BI$9 -> 22.56 | BV5: ='LookUp Roll&Packs'!$CO$9 -> 2796.7 | BW5: ='LookUp Roll&Packs'!$CQ$9 -> 175.14 | BX5: ='LookUp Roll&Packs'!$CP$9 -> 66.8 | BY5: 1 | BZ5: =BU5 -> 22.56 | CA5: =((AI5*BO5)+BV5)/1000 -> 4.86982 | CC5: =(AI5*BR5)/1000 -> 0.25056 | CD5: =BW5/1000 -> 0.17514 | CE5: =BX5/1000 -> 0.0668 | CH5: x | CI5: x | CJ5: x
A6: 10000102 | B6: 10000102 | D6: 10000102 | E6: Active | F6: Yes | G6: Cushioning | H6: PadPak Compact | I6: PP Roll 2p 0.38*180m 50/70gsm PK/PK | L6: PadPak Compact | M6: Roll | N6: 50/70gsm | O6: 50,0 g/m2 +/- 2,0 g/m² (inner layer) ; 70,0 g/m2 +/- 2,5 g/m²(outer layer) | P6: 2 | Q6: Premium Kraft/Premium Kraft | R6: Brown | S6: European Union | T6: 8721284290032 | V6: 0.38 x 180m | W6: 180 ± 2 | X6: 380 -1 +5 | AA6: 8.3 | AB6: 20,4 ± 1 | AD6: 48043158 | AE6: Euro | AG6: 40*PML 50/70 180m | AH6: 0.8 | AI6: 40 | AJ6: 1.2 | AK6: 0.92 | AL6: 0.80 x 1.20 x 0.92m | AM6: Yes | AN6: 356 ±12 | AO6: 332 | AP6: PAP22 | AQ6: FSC Mix Credit | AR6: FSC-C134738 | AS6: RoHS Compliant | AT6: Yes | AV6: 0.85 | AW6: 0.15 | AY6: 0.85 | AZ6: 0 | BA6: 0.15 | BE6: - | BF6: - | BG6: Cushioning is used to protect fragile items during shipping. Packages are often handled with little or no care during transport, so precautions are needed to prevent damage. Shocks and vibration are controlled by cushioning, significantly reducing broken box contents and subsequent returns | BH6: Made using fresh renewable fibers from sustainably managed forests, Ranpak’s Premium Kraft paper provides superior protective performance. Designed to minimize CO2 emissions while fully curbside recyclable, Premium Kraft protects the planet as well as your goods. | BI6: 08/16/2024 11:03 AM | BJ6: Vu, Pierre | BM6: True | BO6: ='LookUp Roll&Packs'!$W$6 -> 92.18 | BT6: =AI6 -> 40 | BU6: ='LookUp Roll&Packs'!$CJ$6 -> 22.56 | BV6: ='LookUp Roll&Packs'!$CO$6 -> 257.38 | BW6: ='LookUp Roll&Packs'!$CQ$6 -> 135 | BY6: 1 | BZ6: =BU6 -> 22.56 | CA6: =((AI6*BO6)+BV6)/1000 -> 3.94458 | CD6: =BW6/1000 -> 0.135 | CH6: x | CI6: x | CJ6: x
A7: 10000106 | B7: 10000106 | D7: 10000106 | E7: Active | F7: Yes | G7: Wrapping | H7: Geami ExBox | I7: GE Exbox 0.51*82m 80/22gsm PK/PK | J7: Geami Exbox is a disposable dispenser box with 82m brown Geami paper and 137m Interleaf paper | K7: NA | L7: NA | M7: ExBox | N7: 80/22gsm | O7: 80,0 g/m2 +/- 3,0 g/m² (inner layer) 22,0 g/m2 +/- 1 g/m²(outer layer) | P7: 2 | Q7: Premium Kraft/Premium Kraft | R7: Brown/White | S7: European Union | V7: 0.51 x 82m | W7: 82 | X7: 0.51 | Y7: Exbox | AA7: 5.8 | AD7: 48043158 | AG7: 24*EXBOX Mini Br DC100%/Wh.IL | AH7: 0.8 | AJ7: 1.2 | AK7: 1 | AL7: 0.80 x 1.20 x 1.00m | AM7: Yes | AN7: 164 | AO7: 139 | AP7: PAP22 | AR7: FSC-C134738 | AS7: RoHS Compliant | AT7: Yes | AV7: 0.85 | AW7: 0.15 | AY7: 0.85 | AZ7: 0 | BA7: 0.15 | BB7: 0 | BC7: 0 | BD7: 0 | BE7: - | BF7: - | BG7: Wrapping is an important element of packaging, it offers surface production and is preventing products from scratching, chipping or denting during shipping | BH7: Made using fresh renewable fibers from sustainably managed forests, Ranpak’s Premium Kraft paper provides superior protective performance. Designed to minimize CO2 emissions while fully curbside recyclable, Premium Kraft protects the planet as well as your goods. | BI7: 08/16/2024 11:03 AM | BJ7: Vu, Pierre | BM7: True | BT7: =AI7 -> 0 | CJ7: x
A8: 10000107 | B8: 10000107 | D8: 10000107 | E8: Active | F8: Yes | G8: Wrapping | H8: Geami ExBox | I8: GE Exbox 0.51*82m 80/22gsm PK/PK W | J8: Geami Exbox is a disposable dispenser box with 82m white Geami paper and 137m Interleaf paper | K8: NA | L8: NA | M8: ExBox | N8: 80/22gsm | O8: 80,0 g/m2 +/- 3,0 g/m² (inner layer) 22,0 g/m2 +/- 1 g/m²(outer layer) | P8: 2 | Q8: Premium Kraft/Premium Kraft | R8: White/White | S8: European Union | V8: 0.51 x 82m | W8: 82 | X8: 0.51 | Y8: Exbox | AA8: 5.8 | AD8: 48043158 | AG8: 24*EXBOX Mini Wh DC100%/Wh.IL | AH8: 0.8 | AJ8: 1.2 | AK8: 1 | AL8: 0.80 x 1.20 x 1.00m | AM8: Yes | AN8: 164 | AO8: 139 | AP8: PAP22 | AR8: FSC-C134738 | AS8: RoHS Compliant | AT8: Yes | AV8: 0.85 | AW8: 0.15 | AY8: 0.85 | AZ8: 0 | BA8: 0.15 | BB8: 0 | BC8: 0 | BD8: 0 | BE8: - | BF8: - | BG8: Wrapping is an important element of packaging, it offers surface production and is preventing products from scratching, chipping or denting during shipping | BH8: Made using fresh renewable fibers from sustainably managed forests, Ranpak’s Premium Kraft paper provides superior protective performance. Designed to minimize CO2 emissions while fully curbside recyclable, Premium Kraft protects the planet as well as your goods. | BI8: 08/16/2024 11:03 AM | BJ8: Vu, Pierre | BM8: True | BT8: =AI8 -> 0 | CJ8: x
A9: 10000110 | B9: 10000110 | D9: 10000110 | E9: Active | F9: Yes | G9: Wrapping | H9: Geami ExBox | I9: GE Exbox 0.51*164m 80gsm PK | J9: Geami Exbox is a disposable dispenser box with 164m brown Geami paper | K9: NA | L9: NA | M9: ExBox | N9: 80gsm | O9: 80,0 g/m2 +/- 3,0 g/m² | P9: 1 | Q9: Premium Kraft | R9: Brown | S9: European Union | V9: 0.51 x 164m | W9: 164 | X9: 0.51 | Y9: Exbox | AA9: 8.2 | AD9: 48043158 | AG9: 30*EXBOX Mini Br DC100%/No.IL | AH9: 0.8 | AJ9: 1.2 | AK9: 1.3 | AL9: 0.80 x 1.20 x 1.30m | AM9: Yes | AN9: 270 | AO9: 245 | AP9: PAP22 | AR9: FSC-C134738 | AS9: RoHS Compliant | AT9: Yes | AV9: 0.85 | AW9: 0.15 | AY9: 0.85 | AZ9: 0 | BA9: 0.15 | BB9: 0 | BC9: 0 | BD9: 0 | BE9: - | BF9: - | BG9: Wrapping is an important element of packaging, it offers surface production and is preventing products from scratching, chipping or denting during shipping | BH9: Made using fresh renewable fibers from sustainably managed forests, Ranpak’s Premium Kraft paper provides superior protective performance. Designed to minimize CO2 emissions while fully curbside recyclable, Premium Kraft protects the planet as well as your goods. | BI9: 08/16/2024 11:03 AM | BJ9: Vu, Pierre | BM9: True | BT9: =AI9 -> 0 | CJ9: x
A10: 10000129 | B10: 10000129 | D10: 10000129 | E10: Active | F10: Yes | G10: Void Fill | H10: FillPak Go | I10: FP Box 1p 0.38*360m 70gsm EL | L10: Fillpak Go | M10: Pack | N10: 70gsm | O10: 70,0 g/m2 +/- 2,5 g/m² | P10: 1 | Q10: Ecoline | R10: Brown | S10: European Union | T10: 8721284290070 | V10: 0.38 x 360m | W10: 360 ± 4 | X10: 380 -1 +5 | Y10: - | AA10: 9.9 | AC10: 23 ± 3 | AD10: 48043158 | AE10: Euro | AG10: 48*Fillpak Go 70 360m | AH10: 0.8 | AI10: 48 | AJ10: 1.2 | AK10: 1.35 | AL10: 0.80 x 1.20 x 1.35m | AM10: Yes | AN10: 484 ±19 | AO10: 475 | AP10: PAP22 | AQ10: FSC Recycled 100% | AR10: FSC-C134738 | AS10: RoHS Compliant | AT10: No | AW10: 1 | AY10: 0 | AZ10: 0 | BA10: 1 | BB10: 98 | BC10: 12 | BD10: 8.2 | BE10: - | BF10: - | BG10: Void Fill is a paper filler material, used to close up the free space in your shipping box and lock products in place. When items are prevented from moving during transit, the chances of breakage go down. A paper-based filler offers excellent physical properties in terms of absorbing shocks and protecting sensitive products, and is also more sustainable than plastic alternatives. | BH10: Ecoline protects boxed items in the most economical way while using 100% recycled post-consumer waste materials. Consumer waste is the same paper that can be recycled in your curbside recycling bin, making Ecoline an exceptionally eco-friendly solution. | BI10: 08/16/2024 11:03 AM | BJ10: Vu, Pierre | BM10: True | BO10: ='LookUp Roll&Packs'!$U$9 -> 43.19 | BR10: ='LookUp Roll&Packs'!$V$9 -> 5.22 | BT10: =AI10 -> 48 | BU10: ='LookUp Roll&Packs'!$BI$9 -> 22.56 | BV10: ='LookUp Roll&Packs'!$CO$9 -> 2796.7 | BW10: ='LookUp Roll&Packs'!$CQ$9 -> 175.14 | BX10: ='LookUp Roll&Packs'!$CP$9 -> 66.8 | BY10: 1 | BZ10: =BU10 -> 22.56 | CA10: =((AI10*BO10)+BV10)/1000 -> 4.86982 | CC10: =(AI10*BR10)/1000 -> 0.25056 | CD10: =BW10/1000 -> 0.17514 | CE10: =BX10/1000 -> 0.0668 | CH10: x | CI10: x | CJ10: x
A11: 10000135 | B11: 10000135 | D11: 10000135 | E11: Not active | F11: Yes | G11: Void Fill | H11: FillPak | I11: FP Pack 1p 0.76*430m 60gsm PK W. | L11: - | M11: Pack | N11: 60gsm | O11: 60,0 g/m2 +/- 2,0 g/m² | P11: 1 | Q11: Premium Kraft | R11: White | S11: European Union | V11: 0.76 x 430m | W11: 430 | X11: 0.76 | Y11: White | AA11: 19.5 | AD11: 48043158 | AE11: Euro | AG11: 24*FS 60 430m white | AH11: 0.8 | AJ11: 1.2 | AK11: 1.2 | AL11: 0.80 x 1.20 x 1.20m | AM11: Yes | AN11: 493.992 | AO11: 469 | AP11: PAP22 | AR11: FSC-C134738 | AS11: RoHS Compliant | AT11: Yes | AV11: 0.85 | AW11: 0.15 | AY11: 0.85 | AZ11: 0 | BA11: 0.15 | BE11: - | BF11: - | BG11: Void Fill is a paper filler material, used to close up the free space in your shipping box and lock products in place. When items are prevented from moving during transit, the chances of breakage go down. A paper-based filler offers excellent physical properties in terms of absorbing shocks and protecting sensitive products, and is also more sustainable than plastic alternatives. | BH11: Made using fresh renewable fibers from sustainably managed forests, Ranpak’s Premium Kraft paper provides superior protective performance. Designed to minimize CO2 emissions while fully curbside recyclable, Premium Kraft protects the planet as well as your goods. | BI11: 08/16/2024 11:03 AM | BJ11: Vu, Pierre | BM11: True | BT11: =AI11 -> 0 | BZ11: =BU11 -> 0 | CA11: =((AI11*BO11)+BV11)/1000 -> 0 | CJ11: x
A12: 10000137 | B12: 10000137 | D12: 10000137 | E12: Active | F12: Yes | G12: Void Fill | H12: FillPak | I12: FP Pack 1p 0.76*400m 50gsm PK | L12: Fillpak ; FillPak High speed ; Fillpak Accufill ; PadPak Senior ; PadPak Senior Plus ; PadPak Senior coiler ; PadPak Senior Plus coiler ; PadPak Light Cushioning | M12: Pack | N12: 50gsm | O12: 50,0 g/m2 +/- 2,0 g/m² | P12: 1 | Q12: Premium Kraft | R12: Brown | S12: European Union | T12: 8721284290087 | V12: 0.76 x 400m | W12: 400 ± 4 | X12: 760 -1 +5 | AA12: 15.1 | AC12: 21 ± 3 | AD12: 48043158 | AE12: Euro | AG12: 24*FH 50 400m | AH12: 0.8 | AI12: 24 | AJ12: 1.2 | AK12: 1.2 | AL12: 0.80 x 1.20 x 1.20m | AM12: Yes | AN12: 391 ±14 | AO12: 363 | AP12: PAP22 | AQ12: FSC Mix Credit | AR12: FSC-C134738 | AS12: RoHS Compliant | AT12: Yes | AV12: 0.85 | AW12: 0.15 | AY12: 0.85 | AZ12: 0 | BA12: 0.15 | BB12: 205 | BC12: 19 | BD12: 9.8 | BE12: - | BF12: - | BG12: Void Fill is a paper filler material, used to close up the free space in your shipping box and lock products in place. When items are prevented from moving during transit, the chances of breakage go down. A paper-based filler offers excellent physical properties in terms of absorbing shocks and protecting sensitive products, and is also more sustainable than plastic alternatives. | BH12: Made using fresh renewable fibers from sustainably managed forests, Ranpak’s Premium Kraft paper provides superior protective performance. Designed to minimize CO2 emissions while fully curbside recyclable, Premium Kraft protects the planet as well as your goods. | BI12: 08/16/2024 11:03 AM | BJ12: Vu, Pierre | BM12: True | BO12: ='LookUp Roll&Packs'!$U$7 -> 80.74 | BR12: ='LookUp Roll&Packs'!$V$7 -> 5.22 | BT12: =AI12 -> 24 | BU12: ='LookUp Roll&Packs'!$BI$7 -> 22.56 | BV12: ='LookUp Roll&Packs'!$CO$7 -> 2796.7 | BW12: ='LookUp Roll&Packs'!$CQ$7 -> 175.14 | BX12: ='LookUp Roll&Packs'!$CP$7 -> 66.8 | BY12: 1 | BZ12: =BU12 -> 22.56 | CA12: =((AI12*BO12)+BV12)/1000 -> 4.73446 | CC12: =(AI12*BR12)/1000 -> 0.12528 | CD12: =BW12/1000 -> 0.17514 | CE12: =BX12/1000 -> 0.0668 | CH12: x | CI12: x | CJ12: x
A13: 10000140 | B13: 10000140 | D13: 10000140 | E13: Active | F13: Yes | G13: Void Fill | H13: FillPak | I13: FP Bulkpack 1p 0.76*12000m 50gsm PK | L13: Fillpak bulk ; FillPak High speed ; Fillpak Accufill ; ; ; ; ; | M13: Bulk | N13: 50gsm | O13: 50,0 g/m2 +/- 2,0 g/m² | P13: 1 | Q13: Premium Kraft | R13: Brown | S13: European Union | T13: 8721284290094 | V13: 0.76 x 12000m | W13: 12000 ± 120 | X13: 760 -1 +5 | Y13: - | AA13: 455 | AC13: 23 ± 3 | AD13: 48043158 | AE13: Euro | AF13: BULK | AG13: 24*FS 50 500m FP BULK | AH13: 0.8 | AI13: 1 | AJ13: 1.2 | AK13: 1.2 | AL13: 0.80 x 1.20 x 1.20m | AM13: Yes | AN13: 482 ±18 | AO13: 455 | AP13: PAP22 | AQ13: FSC Mix Credit | AR13: FSC-C134738 | AS13: RoHS Compliant | AT13: Yes | AV13: 0.85 | AW13: 0.15 | AY13: 0.85 | AZ13: 0 | BA13: 0.15 | BB13: 6,049 | BC13: 567 | BD13: 273.6 | BE13: - | BF13: - | BG13: Void Fill is a paper filler material, used to close up the free space in your shipping box and lock products in place. When items are prevented from moving during transit, the chances of breakage go down. A paper-based filler offers excellent physical properties in terms of absorbing shocks and protecting sensitive products, and is also more sustainable than plastic alternatives. | BH13: Made using fresh renewable fibers from sustainably managed forests, Ranpak’s Premium Kraft paper provides superior protective performance. Designed to minimize CO2 emissions while fully curbside recyclable, Premium Kraft protects the planet as well as your goods. | BI13: 08/16/2024 11:03 AM | BJ13: Vu, Pierre | BM13: True | BT13: =AI13 -> 1 | BU13: 22.56 | BV13: 2796.7 | BW13: ?? | BX13: ?? | BZ13: =BU13 -> 22.56 | CI13: x | CJ13: x
A14: 10000143 | B14: 10000143 | D14: 10000143 | E14: Active | F14: Yes | G14: Void Fill | H14: FillPak | I14: FP Pack 1p 0.57*500m 50gsm RK | L14: Fillpak Stream line ; ; ; ; ; ; ; | M14: Pack | N14: 50gsm | O14: 50,0 g/m2 +/- 2,0 g/m² | P14: 1 | Q14: Recycled Kraft | R14: Brown | S14: European Union | T14: 8721284290100 | V14: 0.57 x 500m | W14: 500 ± 5 | X14: 570 -1 +5 | AA14: 14.2 | AC14: 23 ± 3 | AD14: 48043158 | AE14: Euro | AG14: 32*FSL 50 500m R 22,5" | AH14: 0.8 | AI14: 32 | AJ14: 1.2 | AK14: 1.2 | AL14: 0.80 x 1.20 x 1.20m | AM14: Yes | AN14: 482 ±19 | AO14: 455 | AP14: PAP22 | AQ14: FSC Mix Credit | AR14: FSC-C134738 | AS14: RoHS Compliant | AT14: No | AV14: 0.15 | AW14: 0.85 | AY14: 0.15 | AZ14: 0.3 | BA14: 0.55 | BB14: 168 | BC14: 18 | BD14: 10.1 | BE14: - | BF14: - | BG14: Void Fill is a paper filler material, used to close up the free space in your shipping box and lock products in place. When items are prevented from moving during transit, the chances of breakage go down. A paper-based filler offers excellent physical properties in terms of absorbing shocks and protecting sensitive products, and is also more sustainable than plastic alternatives. | BH14: Recycled Kraft is primarily sourced from the strong fibers of post-industrial recycled paper, which not only ensures high-quality protective performance, but also results in a low carbon footprint along with the curbside recyclability of Ranpak paper. | BI14: 08/16/2024 11:03 AM | BJ14: Vu, Pierre | BM14: True | BO14: ='LookUp Roll&Packs'!$U$8 -> 61.97 | BR14: ='LookUp Roll&Packs'!$V$8 -> 5.22 | BT14: =AI14 -> 32 | BU14: ='LookUp Roll&Packs'!$BI$8 -> 22.56 | BV14: ='LookUp Roll&Packs'!$CO$8 -> 2796.7 | BW14: ='LookUp Roll&Packs'!$CQ$8 -> 175.14 | BX14: ='LookUp Roll&Packs'!$CP$8 -> 66.8 | BY14: 1 | BZ14: =BU14 -> 22.56 | CA14: =((AI14*BO14)+BV14)/1000 -> 4.77974 | CC14: =(AI14*BR14)/1000 -> 0.16704 | CD14: =BW14/1000 -> 0.17514 | CE14: =BX14/1000 -> 0.0668 | CH14: x | CI14: x | CJ14: x
A15: 10000145 | B15: 10000145 | D15: 10000145 | E15: Active | F15: Yes | G15: Void Fill | H15: FillPak | I15: FP Pack 1p 0.57*360m 70gsm RK | L15: Fillpak Stream line ; ; ; ; ; ; ; | M15: Pack | N15: 70gsm | O15: 70,0 g/m2 +/- 2,5 g/m² | P15: 1 | Q15: Recycled Kraft | R15: Brown | S15: European Union | T15: 8721284290117 | V15: 0.57 x 360m | W15: 360 ± 4 | X15: 570 -1 +5 | AA15: 14.3 | AC15: 23 ± 3 | AD15: 48043158 | AE15: Euro | AG15: 32*FSL 70 360m R 22,5" | AH15: 0.8 | AI15: 32 | AJ15: 1.2 | AK15: 1.2 | AL15: 0.80 x 1.20 x 1.20m | AM15: Yes | AN15: 486 ±16 | AO15: 458 | AP15: PAP22 | AQ15: FSC Mix Credit | AR15: FSC-C134738 | AS15: RoHS Compliant | AT15: No | AV15: 0.15 | AW15: 0.85 | AY15: 0.15 | AZ15: 0.3 | BA15: 0.55 | BB15: 169 | BC15: 18 | BD15: 9.9 | BE15: - | BF15: - | BG15: Void Fill is a paper filler material, used to close up the free space in your shipping box and lock products in place. When items are prevented from moving during transit, the chances of breakage go down. A paper-based filler offers excellent physical properties in terms of absorbing shocks and protecting sensitive products, and is also more sustainable than plastic alternatives. | BH15: Recycled Kraft is primarily sourced from the strong fibers of post-industrial recycled paper, which not only ensures high-quality protective performance, but also results in a low carbon footprint along with the curbside recyclability of Ranpak paper. | BI15: 08/16/2024 11:04 AM | BJ15: Vu, Pierre | BM15: True | BO15: ='LookUp Roll&Packs'!$U$8 -> 61.97 | BR15: ='LookUp Roll&Packs'!$V$8 -> 5.22 | BT15: =AI15 -> 32 | BU15: ='LookUp Roll&Packs'!$BI$8 -> 22.56 | BV15: ='LookUp Roll&Packs'!$CO$8 -> 2796.7 | BW15: ='LookUp Roll&Packs'!$CQ$8 -> 175.14 | BX15: ='LookUp Roll&Packs'!$CP$8 -> 66.8 | BY15: 1 | BZ15: =BU15 -> 22.56 | CA15: =((AI15*BO15)+BV15)/1000 -> 4.77974 | CC15: =(AI15*BR15)/1000 -> 0.16704 | CD15: =BW15/1000 -> 0.17514 | CE15: =BX15/1000 -> 0.0668 | CH15: x | CI15: x | CJ15: x
A16: 10000146 | B16: 10000146 | D16: 10000146 | E16: Active | F16: Yes | G16: Void Fill | H16: FillPak | I16: FP Pack 1p 0.57*360m 70gsm EL | L16: Fillpak Stream line ; ; ; ; ; ; ; | M16: Pack | N16: 70gsm | O16: 70,0 g/m2 +/- 2,5 g/m² | P16: 1 | Q16: Ecoline | R16: Brown | S16: European Union | T16: 8721284290124 | V16: 0.57 x 360m | W16: 360 ± 4 | X16: 570 -1 +5 | AA16: 14.3 | AC16: 23 ± 3 | AD16: 48043158 | AE16: Euro | AG16: 32*FSLG 70 360m 22,5"Greenline | AH16: 0.8 | AI16: 32 | AJ16: 1.2 | AK16: 1.2 | AL16: 0.80 x 1.20 x 1.20m | AM16: Yes | AN16: 486 ±16 | AO16: 458 | AP16: PAP22 | AQ16: FSC Recycled 100% | AR16: FSC-C134738 | AS16: RoHS Compliant | AT16: No | AW16: 1 | AY16: 0 | AZ16: 0 | BA16: 1 | BB16: 140 | BC16: 18 | BD16: 11.8 | BE16: - | BF16: - | BG16: Void Fill is a paper filler material, used to close up the free space in your shipping box and lock products in place. When items are prevented from moving during transit, the chances of breakage go down. A paper-based filler offers excellent physical properties in terms of absorbing shocks and protecting sensitive products, and is also more sustainable than plastic alternatives. | BH16: Ecoline protects boxed items in the most economical way while using 100% recycled post-consumer waste materials. Consumer waste is the same paper that can be recycled in your curbside recycling bin, making Ecoline an exceptionally eco-friendly solution. | BI16: 08/16/2024 11:04 AM | BJ16: Vu, Pierre | BM16: True | BO16: ='LookUp Roll&Packs'!$U$8 -> 61.97 | BR16: ='LookUp Roll&Packs'!$V$8 -> 5.22 | BT16: =AI16 -> 32 | BU16: ='LookUp Roll&Packs'!$BI$8 -> 22.56 | BV16: ='LookUp Roll&Packs'!$CO$8 -> 2796.7 | BW16: ='LookUp Roll&Packs'!$CQ$8 -> 175.14 | BX16: ='LookUp Roll&Packs'!$CP$8 -> 66.8 | BY16: 1 | BZ16: =BU16 -> 22.56 | CA16: =((AI16*BO16)+BV16)/1000 -> 4.77974 | CC16: =(AI16*BR16)/1000 -> 0.16704 | CD16: =BW16/1000 -> 0.17514 | CE16: =BX16/1000 -> 0.0668 | CH16: x | CI16: x | CJ16: x
A17: 10000192 | B17: 10000192 | D17: 10000192 | E17: Active | F17: Yes | G17: Wrapping | H17: Geami Wrap'n Go | I17: GE Roll DC 0.51*164m 80gsm PK | J17: Roll with 164m brown Geami paper | K17: Geami MV, Geami Wrap 'n Go | L17: Geami HV, Geami MV, Geami Wrap 'n Go | M17: Roll | N17: 80gsm | O17: 80,0 g/m2 +/- 3,0 g/m² | P17: 1 | Q17: Premium Kraft | R17: Brown | S17: European Union | T17: 8721284290131 | V17: 0.51 x 164m | W17: 164 | X17: 0.51 | AA17: 6.8 | AB17: 17,1 ± 1 | AD17: 48042110 | AG17: 30 * DC 20" 164m | AH17: 0.8 | AI17: 30 | AJ17: 1.2 | AK17: 0.66 | AL17: 0.80 x 1.20 x 0.66m | AM17: Yes | AN17: 228 | AO17: 203 | AP17: PAP22 | AQ17: FSC Mix Credit | AR17: FSC-C134738 | AS17: RoHS Compliant | AT17: Yes | AV17: 0.85 | AW17: 0.15 | AY17: 0.85 | AZ17: 0 | BA17: 0.15 | BB17: 0 | BC17: 0 | BD17: 0 | BE17: - | BF17: - | BG17: Wrapping is an important element of packaging, it offers surface production and is preventing products from scratching, chipping or denting during shipping | BH17: Made using fresh renewable fibers from sustainably managed forests, Ranpak’s Premium Kraft paper provides superior protective performance. Designed to minimize CO2 emissions while fully curbside recyclable, Premium Kraft protects the planet as well as your goods. | BI17: 08/16/2024 11:04 AM | BJ17: Vu, Pierre | BM17: True | BO17: ='LookUp Roll&Packs'!$W$11 -> 182.41 | BT17: =AI17 -> 30 | BU17: ='LookUp Roll&Packs'!$CJ$11 -> 22.56 | BV17: ='LookUp Roll&Packs'!$CO$11 -> 514.76 | BW17: ='LookUp Roll&Packs'!$CQ$11 -> 156.29 | CH17: x | CI17: x | CJ17: x
A18: 10000193 | B18: 10000193 | D18: 10000193 | E18: Active | F18: Yes | G18: Wrapping | H18: Geami HV | I18: GE 500 pc DC 0.51*0.4m 80gsm PK | J18: Geami sheets with in size 50.8 x 40cm that are packed with 500 sheets per box | K18: NA | L18: NA | M18: Carton | N18: 80gsm | O18: 80,0 g/m2 +/- 3,0 g/m² | P18: 1 | Q18: Premium Kraft | R18: Brown | S18: European Union | V18: 0.51 x 0.4m | W18: 0.4 | X18: 0.51 | Y18: Sheets | AA18: 8.9 | AD18: 48043158 | AG18: 48 * DC 20” Sheets 500*0.4m | AH18: 0.8 | AJ18: 1.2 | AK18: 1 | AL18: 0.80 x 1.20 x 1.00m | AM18: Yes | AN18: 450 | AO18: 425 | AP18: PAP22 | AR18: FSC-C134738 | AS18: RoHS Compliant | AT18: Yes | AV18: 0.85 | AW18: 0.15 | AY18: 0.85 | AZ18: 0 | BA18: 0.15 | BB18: 0 | BC18: 0 | BD18: 0 | BE18: - | BF18: - | BG18: Wrapping is an important element of packaging, it offers surface production and is preventing products from scratching, chipping or denting during shipping | BH18: Made using fresh renewable fibers from sustainably managed forests, Ranpak’s Premium Kraft paper provides superior protective performance. Designed to minimize CO2 emissions while fully curbside recyclable, Premium Kraft protects the planet as well as your goods. | BI18: 08/16/2024 11:04 AM | BJ18: Vu, Pierre | BM18: True | BT18: =AI18 -> 0 | BY18: 1 | CJ18: x
A19: 10000194 | B19: 10000194 | D19: 10000194 | E19: Active | F19: Yes | G19: Wrapping | H19: Geami HV | I19: GE Roll DC 0.51*250m 80gsm PK | J19: Roll with 250m brown Geami paper | K19: Geami HV | L19: Geami HV | M19: Roll | N19: 80gsm | O19: 80,0 g/m2 +/- 3,0 g/m² | P19: 1 | Q19: Premium Kraft | R19: Brown | S19: European Union | T19: 8721284290155 | V19: 0.51 x 250m | W19: 250 | X19: 0.51 | AA19: 10.6 | AB19: 20,7 ± 1 | AD19: 48043158 | AG19: 40 * DC 20" 250m | AH19: 0.8 | AI19: 40 | AJ19: 1.2 | AK19: 1.17 | AL19: 0.80 x 1.20 x 1.17m | AM19: Yes | AN19: 450 | AO19: 425 | AP19: PAP22 | AQ19: FSC Mix Credit | AR19: FSC-C134738 | AS19: RoHS Compliant | AT19: Yes | AV19: 0.85 | AW19: 0.15 | AY19: 0.85 | AZ19: 0 | BA19: 0.15 | BB19: 0 | BC19: 0 | BD19: 0 | BE19: - | BF19: - | BG19: Wrapping is an important element of packaging, it offers surface production and is preventing products from scratching, chipping or denting during shipping | BH19: Made using fresh renewable fibers from sustainably managed forests, Ranpak’s Premium Kraft paper provides superior protective performance. Designed to minimize CO2 emissions while fully curbside recyclable, Premium Kraft protects the planet as well as your goods. | BI19: 08/16/2024 11:04 AM | BJ19: Vu, Pierre | BM19: True | BO19: ='LookUp Roll&Packs'!$W$11 -> 182.41 | BT19: =AI19 -> 40 | BU19: ='LookUp Roll&Packs'!$CJ$11 -> 22.56 | BV19: ='LookUp Roll&Packs'!$CO$11 -> 514.76 | BW19: ='LookUp Roll&Packs'!$CQ$11 -> 156.29 | BY19: 1 | BZ19: =BU19 -> 22.56 | CA19: =((AI19*BO19)+BV19)/1000 -> 7.81116 | CD19: =BW19/1000 -> 0.15629 | CH19: x | CI19: x | CJ19: x
A20: 10000195 | B20: 10000195 | D20: 10000195 | E20: Active | F20: Yes | G20: Wrapping | H20: Geami HV | I20: GE Roll DC 0.51*250m 80gsm PK W. | J20: Roll with 250m white Geami paper | K20: Geami HV | L20: Geami HV | M20: Roll | N20: 80gsm | O20: 80,0 g/m2 +/- 3,0 g/m² | P20: 1 | Q20: Premium Kraft | R20: White | S20: European Union | T20: 8721284290162 | V20: 0.51 x 250m | W20: 250 | X20: 0.51 | Y20: White | AA20: 10.6 | AB20: 20,7 ± 1 | AD20: 48043158 | AG20: 40 * DC 20" 250m white | AH20: 0.8 | AI20: 40 | AJ20: 1.2 | AK20: 1.17 | AL20: 0.80 x 1.20 x 1.17m | AM20: Yes | AN20: 450 | AO20: 425 | AP20: PAP22 | AQ20: FSC Mix Credit | AR20: FSC-C134738 | AS20: RoHS Compliant | AT20: Yes | AV20: 0.85 | AW20: 0.15 | AY20: 0.85 | AZ20: 0 | BA20: 0.15 | BB20: 0 | BC20: 0 | BD20: 0 | BE20: - | BF20: - | BG20: Wrapping is an important element of packaging, it offers surface production and is preventing products from scratching, chipping or denting during shipping | BH20: Made using fresh renewable fibers from sustainably managed forests, Ranpak’s Premium Kraft paper provides superior protective performance. Designed to minimize CO2 emissions while fully curbside recyclable, Premium Kraft protects the planet as well as your goods. | BI20: 08/16/2024 11:04 AM | BJ20: Vu, Pierre | BM20: True | BO20: ='LookUp Roll&Packs'!$W$11 -> 182.41 | BT20: =AI20 -> 40 | BU20: ='LookUp Roll&Packs'!$CJ$11 -> 22.56 | BV20: ='LookUp Roll&Packs'!$CO$11 -> 514.76 | BW20: ='LookUp Roll&Packs'!$CQ$11 -> 156.29 | BY20: 1 | BZ20: =BU20 -> 22.56 | CA20: =((AI20*BO20)+BV20)/1000 -> 7.81116 | CD20: =BW20/1000 -> 0.15629 | CH20: x | CI20: x | CJ20: x
A21: 10000365 | B21: 10000365 | D21: 10000365 | E21: Active | F21: Yes | G21: Wrapping | H21: Geami HV | I21: GE Roll IL 0.3*840m 22gsm PK | J21: Roll with 840m white Interleaf paper | K21: Geami HV | L21: Geami HV | M21: Roll | N21: 22gsm | O21: 22,0 g/m2 +/- 1,0 g/m² | P21: 1 | Q21: Premium Kraft | R21: White | S21: European Union | T21: 8721284290179 | V21: 0.3 x 840m | W21: 840 | X21: 0.3 | AA21: 5.8 | AB21: 19,9 ± 1 | AD21: 48043951 | AG21: 20 * IL 12" 840m white | AH21: 0.8 | AI21: 20 | AJ21: 1.2 | AK21: 0.46 | AL21: 0.80 x 1.20 x 0.46m | AM21: Yes | AN21: 140 | AO21: 115 | AP21: PAP22 | AQ21: FSC Mix Credit | AR21: FSC-C134738 | AS21: RoHS Compliant | AT21: Yes | AV21: 0.85 | AW21: 0.15 | AY21: 0.85 | AZ21: 0 | BA21: 0.15 | BB21: 0 | BC21: 0 | BD21: 0 | BE21: - | BG21: Wrapping is an important element of packaging, it offers surface production and is preventing products from scratching, chipping or denting during shipping | BH21: Made using fresh renewable fibers from sustainably managed forests, Ranpak’s Premium Kraft paper provides superior protective performance. Designed to minimize CO2 emissions while fully curbside recyclable, Premium Kraft protects the planet as well as your goods. | BI21: 08/16/2024 11:04 AM | BJ21: Vu, Pierre | BM21: True | BO21: ='LookUp Roll&Packs'!$E$12 -> 110 | BT21: =AI21 -> 20 | BU21: ='LookUp Roll&Packs'!$CJ$12 -> 22.56 | BV21: ='LookUp Roll&Packs'!$CO$12 -> 514.76 | BW21: ='LookUp Roll&Packs'!$CQ$12 -> 100 | BY21: 1 | BZ21: =BU21 -> 22.56 | CA21: =((AI21*BO21)+BV21)/1000 -> 2.71476 | CD21: =BW21/1000 -> 0.1 | CH21: x | CI21: x | CJ21: x
A22: 10000368 | B22: 10000368 | D22: 10000368 | E22: Active | F22: Yes | G22: Wrapping | H22: Geami HV | I22: GE Roll IL 0.3*840m 22gsm PK B. | J22: Roll with 840m black Interleaf paper | K22: Geami HV | L22: Geami HV | M22: Roll | N22: 22gsm | O22: 22,0 g/m2 +/- 1,0 g/m² | P22: 1 | Q22: Premium Kraft | R22: Black | S22: European Union | V22: 0.3 x 840m | W22: 840 | X22: 0.3 | Y22: Black | AA22: 5.8 | AD22: 48053000 | AG22: 20*IL 12" 840m BLACK | AH22: 0.8 | AI22: 20 | AJ22: 1.2 | AK22: 0.46 | AL22: 0.80 x 1.20 x 0.46m | AM22: Yes | AN22: 140 | AO22: 115 | AP22: PAP22 | AR22: FSC-C134738 | AS22: RoHS Compliant | AT22: Yes | AV22: 0.85 | AW22: 0.15 | AY22: 0.85 | AZ22: 0 | BA22: 0.15 | BB22: 0 | BC22: 0 | BD22: 0 | BE22: - | BF22: - | BG22: Wrapping is an important element of packaging, it offers surface production and is preventing products from scratching, chipping or denting during shipping | BH22: Made using fresh renewable fibers from sustainably managed forests, Ranpak’s Premium Kraft paper provides superior protective performance. Designed to minimize CO2 emissions while fully curbside recyclable, Premium Kraft protects the planet as well as your goods. | BI22: 08/16/2024 11:04 AM | BJ22: Vu, Pierre | BM22: True | BO22: ='LookUp Roll&Packs'!$E$12 -> 110 | BT22: =AI22 -> 20 | BU22: ='LookUp Roll&Packs'!$CJ$12 -> 22.56 | BV22: ='LookUp Roll&Packs'!$CO$12 -> 514.76 | BW22: ='LookUp Roll&Packs'!$CQ$12 -> 100 | BY22: 1 | BZ22: =BU22 -> 22.56 | CA22: =((AI22*BO22)+BV22)/1000 -> 2.71476 | CD22: =BW22/1000 -> 0.1 | CH22: x | CI22: x | CJ22: x
A23: 10000398 | B23: 10000398 | D23: 10000398 | E23: Active | F23: Yes | G23: Cushioning | H23: PadPak Junior | I23: PP Roll 2p 0.69*215m 50/50gsm PK/PK | L23: PadPak Junior ; ; ; ; ; ; ; | M23: Roll | N23: 50/50gsm | O23: 50,0 g/m2 +/- 2,0 g/m²(inner layer) ; 50,0 g/m2 +/- 2,0 g/m²(outer layer) | P23: 2 | Q23: Premium Kraft/Premium Kraft | R23: Brown | S23: European Union | T23: 8721284290193 | V23: 0.69 x 215m | W23: 215 ± 2 | X23: 680 -1 +5 | AA23: 14.5 | AB23: 20,7 ± 1 | AD23: 48043158 | AE23: Euro | AG23: 20*PJS 50/50 215m junior | AH23: 0.8 | AI23: 20 | AJ23: 1.2 | AK23: 0.83 | AL23: 0.80 x 1.20 x 0.83m | AM23: Yes | AN23: 318 ±12 | AO23: 290 | AP23: PAP22 | AQ23: FSC Mix Credit | AR23: FSC-C134738 | AS23: RoHS Compliant | AT23: Yes | AV23: 0.85 | AW23: 0.15 | AY23: 0.85 | AZ23: 0 | BA23: 0.15 | BE23: - | BF23: - | BG23: Cushioning is used to protect fragile items during shipping. Packages are often handled with little or no care during transport, so precautions are needed to prevent damage. Shocks and vibration are controlled by cushioning, significantly reducing broken box contents and subsequent returns | BH23: Made using fresh renewable fibers from sustainably managed forests, Ranpak’s Premium Kraft paper provides superior protective performance. Designed to minimize CO2 emissions while fully curbside recyclable, Premium Kraft protects the planet as well as your goods. | BI23: 08/16/2024 11:04 AM | BJ23: Vu, Pierre | BM23: True | BO23: ='LookUp Roll&Packs'!$W$5 -> 156.92 | BT23: =AI23 -> 20 | BU23: ='LookUp Roll&Packs'!$CJ$5 -> 22.56 | BV23: ='LookUp Roll&Packs'!$CO$5 -> 257.38 | BW23: ='LookUp Roll&Packs'!$CQ$5 -> 135 | BY23: 1 | BZ23: =BU23 -> 22.56 | CA23: =((AI23*BO23)+BV23)/1000 -> 3.39578 | CC23: =(AI23*BR23)/1000 -> 0 | CD23: =BW23/1000 -> 0.135 | CE23: =BX23/1000 -> 0 | CH23: x | CI23: x | CJ23: x
A24: 10000411 | B24: 10000411 | C24: 24*PF 70 360m 30" Ecoline | D24: 10000411 | AG24: 24*PF 70 360m 30" Ecoline | AI24: 24 | BO24: ='LookUp Roll&Packs'!$U$7 -> 80.74 | BR24: ='LookUp Roll&Packs'!$V$7 -> 5.22 | BT24: 24 | BU24: ='LookUp Roll&Packs'!$CJ$7 -> 22.56 | BV24: ='LookUp Roll&Packs'!$CO$7 -> 2796.7 | BW24: ='LookUp Roll&Packs'!$CQ$7 -> 175.14 | BX24: ='LookUp Roll&Packs'!$CP$7 -> 66.8 | BY24: 1 | BZ24: =BU24 -> 22.56 | CA24: =((AI24*BO24)+BV24)/1000 -> 4.73446 | CC24: =(AI24*BR24)/1000 -> 0.12528 | CD24: =BW24/1000 -> 0.17514 | CE24: =BX24/1000 -> 0.0668
A25: 10000416 | B25: 10000416 | C25: 24*PF 90 300m 30" Ecoline | D25: 10000416 | AG25: 24*PF 90 300m 30" Ecoline | AI25: 24 | BO25: ='LookUp Roll&Packs'!$U$7 -> 80.74 | BR25: ='LookUp Roll&Packs'!$V$7 -> 5.22 | BT25: 24 | BU25: ='LookUp Roll&Packs'!$CJ$7 -> 22.56 | BV25: ='LookUp Roll&Packs'!$CO$7 -> 2796.7 | BW25: ='LookUp Roll&Packs'!$CQ$7 -> 175.14 | BX25: ='LookUp Roll&Packs'!$CP$7 -> 66.8 | BY25: 1 | BZ25: =BU25 -> 22.56 | CA25: =((AI25*BO25)+BV25)/1000 -> 4.73446 | CC25: =(AI25*BR25)/1000 -> 0.12528 | CD25: =BW25/1000 -> 0.17514 | CE25: =BX25/1000 -> 0.0668
A26: 10000418 | B26: 10000418 | C26: 24*PF 90 300m 30" R | D26: 10000418 | AG26: 24*PF 90 300m 30" R | AI26: 24 | BO26: ='LookUp Roll&Packs'!$U$7 -> 80.74 | BR26: ='LookUp Roll&Packs'!$V$7 -> 5.22 | BT26: 24 | BU26: ='LookUp Roll&Packs'!$CJ$7 -> 22.56 | BV26: ='LookUp Roll&Packs'!$CO$7 -> 2796.7 | BW26: ='LookUp Roll&Packs'!$CQ$7 -> 175.14 | BX26: ='LookUp Roll&Packs'!$CP$7 -> 66.8 | BY26: 1 | BZ26: =BU26 -> 22.56 | CA26: =((AI26*BO26)+BV26)/1000 -> 4.73446 | CC26: =(AI26*BR26)/1000 -> 0.12528 | CD26: =BW26/1000 -> 0.17514 | CE26: =BX26/1000 -> 0.0668
A27: 10000420 | B27: 10000420 | C27: 24*PF 90 300m | D27: 10000420 | AG27: 24*PF 90 300m | AI27: 24 | BO27: ='LookUp Roll&Packs'!$U$7 -> 80.74 | BR27: ='LookUp Roll&Packs'!$V$7 -> 5.22 | BT27: 24 | BU27: ='LookUp Roll&Packs'!$CJ$7 -> 22.56 | BV27: ='LookUp Roll&Packs'!$CO$7 -> 2796.7 | BW27: ='LookUp Roll&Packs'!$CQ$7 -> 175.14 | BX27: ='LookUp Roll&Packs'!$CP$7 -> 66.8 | BY27: 1 | BZ27: =BU27 -> 22.56 | CA27: =((AI27*BO27)+BV27)/1000 -> 4.73446 | CC27: =(AI27*BR27)/1000 -> 0.12528 | CD27: =BW27/1000 -> 0.17514 | CE27: =BX27/1000 -> 0.0668
A28: 10000426 | B28: 10000426 | D28: 10000426 | E28: Active | F28: Yes | G28: Cushioning | H28: PadPak LC | I28: PP Bulkpack 1p 0.76*8640m 70gsm EL | L28: PadPak Light Cushioning Plus Bulk ; ; ; ; ; ; ; | M28: Bulk | N28: 70gsm | O28: 70,0 g/m2 +/- 2,5 g/m² | P28: 1 | Q28: Ecoline | R28: Brown | S28: European Union | T28: 8721284290209 | V28: 0.76 x 8640m | W28: 8640 ± 86 | X28: 760 -1 +5 | AA28: 472 | AC28: 105 ± 10 | AD28: 48043158 | AE28: Euro | AF28: BULK | AG28: PF 70 8.640m 30" Ecoline BULK | AH28: 0.8 | AI28: 1 | AJ28: 1.2 | AK28: 1.2 | AL28: 0.80 x 1.20 x 1.20m | AM28: Yes | AN28: 486 ±16 | AO28: 472 | AP28: PAP22 | AQ28: FSC Recycled 100% | AR28: FSC-C134738 | AS28: RoHS Compliant | AT28: No | AW28: 1 | AY28: 0 | AZ28: 0 | BA28: 1 | BB28: 4,422 | BC28: 574 | BD28: 384.1 | BE28: - | BF28: - | BG28: Cushioning is used to protect fragile items during shipping. Packages are often handled with little or no care during transport, so precautions are needed to prevent damage. Shocks and vibration are controlled by cushioning, significantly reducing broken box contents and subsequent returns | BH28: Ecoline protects boxed items in the most economical way while using 100% recycled post-consumer waste materials. Consumer waste is the same paper that can be recycled in your curbside recycling bin, making Ecoline an exceptionally eco-friendly solution | BI28: 08/16/2024 11:04 AM | BJ28: Vu, Pierre | BM28: True | BT28: =AI28 -> 1 | BU28: ='LookUp Roll&Packs'!$CJ$7 -> 22.56 | BV28: ='LookUp Roll&Packs'!$CO$7 -> 2796.7 | BW28: ='LookUp Roll&Packs'!$CQ$7 -> 175.14 | BX28: ='LookUp Roll&Packs'!$CP$7 -> 66.8 | BY28: 1 | BZ28: =BU28 -> 22.56 | CA28: =((AI28*BO28)+BV28)/1000 -> 2.7967 | CC28: =(AI28*BR28)/1000 -> 0 | CD28: =BW28/1000 -> 0.17514 | CE28: =BX28/1000 -> 0.0668 | CH28: x | CI28: x | CJ28: x
A29: 10000427 | B29: 10000427 | D29: 10000427 | E29: Active | F29: Yes | G29: Cushioning | H29: PadPak LC | I29: PP Bulkpack 1p 0.76*8640m 70gsm PK | L29: PadPak Light Cushioning Bulk ; PadPak Light Cushioning Plus Bulk ; ; ; ; ; ; | M29: Bulk | N29: 70gsm | O29: 70,0 g/m2 +/- 2,5 g/m² | P29: 1 | Q29: Premium Kraft | R29: Brown | S29: European Union | T29: 8721284290216 | V29: 0.76 x 8640m | W29: 8640 ± 86 | X29: 760 -1 +5 | AA29: 458 | AC29: 105 ± 10 | AD29: 48043158 | AE29: Euro | AF29: BULK | AG29: 24*PF 70 360m LC BULK | AH29: 0.8 | AI29: 1 | AJ29: 1.2 | AK29: 1.2 | AL29: 0.80 x 1.20 x 1.20m | AM29: Yes | AN29: 486 ±16 | AO29: 458 | AP29: PAP22 | AQ29: FSC Mix Credit | AR29: FSC-C134738 | AS29: RoHS Compliant | AT29: Yes | AV29: 0.85 | AW29: 0.15 | AY29: 0.85 | AZ29: 0 | BA29: 0.15 | BB29: 6,097 | BC29: 572 | BD29: 275.2 | BE29: - | BF29: - | BG29: Cushioning is used to protect fragile items during shipping. Packages are often handled with little or no care during transport, so precautions are needed to prevent damage. Shocks and vibration are controlled by cushioning, significantly reducing broken box contents and subsequent returns | BH29: Made using fresh renewable fibers from sustainably managed forests, Ranpak’s Premium Kraft paper provides superior protective performance. Designed to minimize CO2 emissions while fully curbside recyclable, Premium Kraft protects the planet as well as your goods. | BI29: 08/16/2024 11:04 AM | BJ29: Vu, Pierre | BM29: True | BT29: =AI29 -> 1 | BU29: ='LookUp Roll&Packs'!$CJ$7 -> 22.56 | BV29: ='LookUp Roll&Packs'!$CO$7 -> 2796.7 | BW29: ='LookUp Roll&Packs'!$CQ$7 -> 175.14 | BX29: ='LookUp Roll&Packs'!$CP$7 -> 66.8 | BY29: 1 | BZ29: =BU29 -> 22.56 | CA29: =((AI29*BO29)+BV29)/1000 -> 2.7967 | CC29: =(AI29*BR29)/1000 -> 0 | CD29: =BW29/1000 -> 0.17514 | CE29: =BX29/1000 -> 0.0668 | CH29: x | CI29: x | CJ29: x
